Workbook

Sheet Start Here
A1: LogicScript Expense Tracker
A2: A free tracker that checks its own entries. Made for freelancers and small businesses.
A4: How to use it
A5: 1. Settings tab: set your tax year, your two review rules, and your categories (yellow cells).
A6: 2. Expenses tab: delete the rows marked EXAMPLE, then type one expense per row in the yellow columns.
A7: 3. Watch the Status column: ERROR = fix it (left out of totals), CHECK = counted but review it, OK = passed.
A8: 4. Summary tab: you are done when it says ALL CHECKS PASSED.
A10: What the rules check
A11: Date: missing, not a real date, outside your tax year, or in the future.
A12: Amount: missing, not a number, or zero/negative (refunds: record them separately in Notes).
A13: Category: missing or not in your list (catches typos that slip past the dropdown when pasting).
A14: Duplicate: same date, vendor and amount entered more than once.
... A24: Works in Google Sheets (File > Make a copy), Microsoft Excel and LibreOffice. Your data stays in your own copy.

Sheet Expenses
A1: Expenses
A2: Type in the yellow columns. Each grey "rule" column checks one thing. Status: ERROR = left out of totals until fixed; CHECK = counted, but please review; OK = passed every rule.
A3: Rows marked EXAMPLE contain deliberate mistakes so you can see the checks work. Delete them before you start.
K4: Rule columns: do not type here
A5: Date | B5: Vendor | C5: Description | D5: Category | E5: Amount | F5: Payment method | G5: Receipt saved? | H5: Notes | I5: Status | J5: Issues | K5: Rule: date | L5: Rule: amount | M5: Rule: category | N5: Rule: duplicate | O5: Rule: receipt | P5: Rule: size
A6: 46027 | B6: Office supply store | C6: Printer paper and toner | D6: Office supplies | E6: 48.2 | F6: Card | G6: Yes | H6: EXAMPLE - delete | I6: =IF(NOT(COUNTA($A6:$H6)>0),"",IF(K6&L6&M6<>"","ERROR",IF(N6&O6&P6<>"","CHECK","OK"))) -> OK | J6: =TRIM(K6&L6&M6&N6&O6&P6) | K6: =IF(NOT(COUNTA($A6:$H6)>0),"",IF(A6="","Missing date. ",IF(NOT(ISNUMBER(A6)),"Date is not a real date. ",IF(YEAR(A6)<>Settings!$B$4,"Date outside tax year. ",IF(A6>TODAY(),"Date is in the future. ",""))))) | L6: =IF(NOT(COUNTA($A6:$H6)>0),"",IF(E6="","Missing amount. ",IF(NOT(ISNUMBER(E6)),"Amount is not a number. ",IF(E6<=0,"Amount must be above zero. ","")))) | M6: =IF(NOT(COUNTA($A6:$H6)>0),"",IF(D6="","Missing category. ",IF(COUNTIF(Settings!$B$11:$B$40,D6)=0,"Category not in your list. ",""))) | N6: =IF(AND(ISNUMBER(A6),ISNUMBER(E6),B6<>""),IF(COUNTIFS($A$6:$A$505,A6,$B$6:$B$505,B6,$E$6:$E$505,E6)>1,"Possible duplicate. ",""),"") | O6: =IF(AND(ISNUMBER(E6),E6>=Settings!$B$6,G6<>"Yes"),"Receipt not marked as saved. ","") | P6: =IF(AND(ISNUMBER(E6),E6>=Settings!$B$5),"Large amount: review. ","")
A7: 46034 | B7: Design software co. | C7: Monthly subscription | D7: Software & subscriptions | E7: 59.99 | F7: Card | G7: Yes | H7: EXAMPLE - delete | I7: =IF(NOT(COUNTA($A7:$H7)>0),"",IF(K7&L7&M7<>"","ERROR",IF(N7&O7&P7<>"","CHECK","OK"))) -> CHECK | J7: =TRIM(K7&L7&M7&N7&O7&P7) -> Possible duplicate. | K7: =IF(NOT(COUNTA($A7:$H7)>0),"",IF(A7="","Missing date. ",IF(NOT(ISNUMBER(A7)),"Date is not a real date. ",IF(YEAR(A7)<>Settings!$B$4,"Date outside tax year. ",IF(A7>TODAY(),"Date is in the future. ",""))))) | L7: =IF(NOT(COUNTA($A7:$H7)>0),"",IF(E7="","Missing amount. ",IF(NOT(ISNUMBER(E7)),"Amount is not a number. ",IF(E7<=0,"Amount must be above zero. ","")))) | M7: =IF(NOT(COUNTA($A7:$H7)>0),"",IF(D7="","Missing category. ",IF(COUNTIF(Settings!$B$11:$B$40,D7)=0,"Category not in your list. ",""))) | N7: =IF(AND(ISNUMBER(A7),ISNUMBER(E7),B7<>""),IF(COUNTIFS($A$6:$A$505,A7,$B$6:$B$505,B7,$E$6:$E$505,E7)>1,"Possible duplicate. ",""),"") -> Possible duplicate. | O7: =IF(AND(ISNUMBER(E7),E7>=Settings!$B$6,G7<>"Yes"),"Receipt not marked as saved. ","") | P7: =IF(AND(ISNUMBER(E7),E7>=Settings!$B$5),"Large amount: review. ","")
A8: 46034 | B8: Design software co. | C8: Monthly subscription | D8: Software & subscriptions | E8: 59.99 | F8: Card | G8: Yes | H8: EXAMPLE - delete | I8: =IF(NOT(COUNTA($A8:$H8)>0),"",IF(K8&L8&M8<>"","ERROR",IF(N8&O8&P8<>"","CHECK","OK"))) -> CHECK | J8: =TRIM(K8&L8&M8&N8&O8&P8) -> Possible duplicate. | K8: =IF(NOT(COUNTA($A8:$H8)>0),"",IF(A8="","Missing date. ",IF(NOT(ISNUMBER(A8)),"Date is not a real date. ",IF(YEAR(A8)<>Settings!$B$4,"Date outside tax year. ",IF(A8>TODAY(),"Date is in the future. ",""))))) | L8: =IF(NOT(COUNTA($A8:$H8)>0),"",IF(E8="","Missing amount. ",IF(NOT(ISNUMBER(E8)),"Amount is not a number. ",IF(E8<=0,"Amount must be above zero. ","")))) | M8: =IF(NOT(COUNTA($A8:$H8)>0),"",IF(D8="","Missing category. ",IF(COUNTIF(Settings!$B$11:$B$40,D8)=0,"Category not in your list. ",""))) | N8: =IF(AND(ISNUMBER(A8),ISNUMBER(E8),B8<>""),IF(COUNTIFS($A$6:$A$505,A8,$B$6:$B$505,B8,$E$6:$E$505,E8)>1,"Possible duplicate. ",""),"") -> Possible duplicate. | O8: =IF(AND(ISNUMBER(E8),E8>=Settings!$B$6,G8<>"Yes"),"Receipt not marked as saved. ","") | P8: =IF(AND(ISNUMBER(E8),E8>=Settings!$B$5),"Large amount: review. ","")
A9: 46056 | B9: Airline | C9: Flight to client meeting | D9: Travel | E9: 412.3 | F9: Card | H9: EXAMPLE - delete | I9: =IF(NOT(COUNTA($A9:$H9)>0),"",IF(K9&L9&M9<>"","ERROR",IF(N9&O9&P9<>"","CHECK","OK"))) -> CHECK | J9: =TRIM(K9&L9&M9&N9&O9&P9) -> Receipt not marked as saved. | K9: =IF(NOT(COUNTA($A9:$H9)>0),"",IF(A9="","Missing date. ",IF(NOT(ISNUMBER(A9)),"Date is not a real date. ",IF(YEAR(A9)<>Settings!$B$4,"Date outside tax year. ",IF(A9>TODAY(),"Date is in the future. ",""))))) | L9: =IF(NOT(COUNTA($A9:$H9)>0),"",IF(E9="","Missing amount. ",IF(NOT(ISNUMBER(E9)),"Amount is not a number. ",IF(E9<=0,"Amount must be above zero. ","")))) | M9: =IF(NOT(COUNTA($A9:$H9)>0),"",IF(D9="","Missing category. ",IF(COUNTIF(Settings!$B$11:$B$40,D9)=0,"Category not in your list. ",""))) | N9: =IF(AND(ISNUMBER(A9),ISNUMBER(E9),B9<>""),IF(COUNTIFS($A$6:$A$505,A9,$B$6:$B$505,B9,$E$6:$E$505,E9)>1,"Possible duplicate. ",""),"") | O9: =IF(AND(ISNUMBER(E9),E9>=Settings!$B$6,G9<>"Yes"),"Receipt not marked as saved. ","") -> Receipt not marked as saved. | P9: =IF(AND(ISNUMBER(E9),E9>=Settings!$B$5),"Large amount: review. ","")
A10: 46067 | B10: Corner cafe | C10: Client lunch | D10: Meal | E10: 38.75 | F10: Card | G10: Yes | H10: EXAMPLE - delete | I10: =IF(NOT(COUNTA($A10:$H10)>0),"",IF(K10&L10&M10<>"","ERROR",IF(N10&O10&P10<>"","CHECK","OK"))) -> ERROR | J10: =TRIM(K10&L10&M10&N10&O10&P10) -> Category not in your list. | K10: =IF(NOT(COUNTA($A10:$H10)>0),"",IF(A10="","Missing date. ",IF(NOT(ISNUMBER(A10)),"Date is not a real date. ",IF(YEAR(A10)<>Settings!$B$4,"Date outside tax year. ",IF(A10>TODAY(),"Date is in the future. ",""))))) | L10: =IF(NOT(COUNTA($A10:$H10)>0),"",IF(E10="","Missing amount. ",IF(NOT(ISNUMBER(E10)),"Amount is not a number. ",IF(E10<=0,"Amount must be above zero. ","")))) | M10: =IF(NOT(COUNTA($A10:$H10)>0),"",IF(D10="","Missing category. ",IF(COUNTIF(Settings!$B$11:$B$40,D10)=0,"Category not in your list. ",""))) -> Category not in your list. | N10: =IF(AND(ISNUMBER(A10),ISNUMBER(E10),B10<>""),IF(COUNTIFS($A$6:$A$505,A10,$B$6:$B$505,B10,$E$6:$E$505,E10)>1,"Possible duplicate. ",""),"") | O10: =IF(AND(ISNUMBER(E10),E10>=Settings!$B$6,G10<>"Yes"),"Receipt not marked as saved. ","") | P10: =IF(AND(ISNUMBER(E10),E10>=Settings!$B$5),"Large amount: review. ","")
A11: 46082 | B11: Internet provider | C11: March internet | D11: Phone & internet | E11: -89.99 | F11: Bank transfer | G11: Yes | H11: EXAMPLE - delete | I11: =IF(NOT(COUNTA($A11:$H11)>0),"",IF(K11&L11&M11<>"","ERROR",IF(N11&O11&P11<>"","CHECK","OK"))) -> ERROR | J11: =TRIM(K11&L11&M11&N11&O11&P11) -> Amount must be above zero. | K11: =IF(NOT(COUNTA($A11:$H11)>0),"",IF(A11="","Missing date. ",IF(NOT(ISNUMBER(A11)),"Date is not a real date. ",IF(YEAR(A11)<>Settings!$B$4,"Date outside tax year. ",IF(A11>TODAY(),"Date is in the future. ",""))))) | L11: =IF(NOT(COUNTA($A11:$H11)>0),"",IF(E11="","Missing amount. ",IF(NOT(ISNUMBER(E11)),"Amount is not a number. ",IF(E11<=0,"Amount must be above zero. ","")))) -> Amount must be above zero. | M11: =IF(NOT(COUNTA($A11:$H11)>0),"",IF(D11="","Missing category. ",IF(COUNTIF(Settings!$B$11:$B$40,D11)=0,"Category not in your list. ",""))) | N11: =IF(AND(ISNUMBER(A11),ISNUMBER(E11),B11<>""),IF(COUNTIFS($A$6:$A$505,A11,$B$6:$B$505,B11,$E$6:$E$505,E11)>1,"Possible duplicate. ",""),"") | O11: =IF(AND(ISNUMBER(E11),E11>=Settings!$B$6,G11<>"Yes"),"Receipt not marked as saved. ","") | P11: =IF(AND(ISNUMBER(E11),E11>=Settings!$B$5),"Large amount: review. ","")
A12: 46021 | B12: Computer store | C12: Laptop | D12: Equipment | E12: 1299 | F12: Card | G12: Yes | H12: EXAMPLE - delete | I12: =IF(NOT(COUNTA($A12:$H12)>0),"",IF(K12&L12&M12<>"","ERROR",IF(N12&O12&P12<>"","CHECK","OK"))) -> ERROR | J12: =TRIM(K12&L12&M12&N12&O12&P12) -> Date outside tax year. Large amount: review. | K12: =IF(NOT(COUNTA($A12:$H12)>0),"",IF(A12="","Missing date. ",IF(NOT(ISNUMBER(A12)),"Date is not a real date. ",IF(YEAR(A12)<>Settings!$B$4,"Date outside tax year. ",IF(A12>TODAY(),"Date is in the future. ",""))))) -> Date outside tax year. | L12: =IF(NOT(COUNTA($A12:$H12)>0),"",IF(E12="","Missing amount. ",IF(NOT(ISNUMBER(E12)),"Amount is not a number. ",IF(E12<=0,"Amount must be above zero. ","")))) | M12: =IF(NOT(COUNTA($A12:$H12)>0),"",IF(D12="","Missing category. ",IF(COUNTIF(Settings!$B$11:$B$40,D12)=0,"Category not in your list. ",""))) | N12: =IF(AND(ISNUMBER(A12),ISNUMBER(E12),B12<>""),IF(COUNTIFS($A$6:$A$505,A12,$B$6:$B$505,B12,$E$6:$E$505,E12)>1,"Possible duplicate. ",""),"") | O12: =IF(AND(ISNUMBER(E12),E12>=Settings!$B$6,G12<>"Yes"),"Receipt not marked as saved. ","") | P12: =IF(AND(ISNUMBER(E12),E12>=Settings!$B$5),"Large amount: review. ","") -> Large amount: review.
A13: 46096 | B13: Office landlord | C13: March office rent | D13: Rent | E13: 1200 | F13: Bank transfer | G13: Yes | H13: EXAMPLE - delete | I13: =IF(NOT(COUNTA($A13:$H13)>0),"",IF(K13&L13&M13<>"","ERROR",IF(N13&O13&P13<>"","CHECK","OK"))) -> CHECK | J13: =TRIM(K13&L13&M13&N13&O13&P13) -> Large amount: review. | K13: =IF(NOT(COUNTA($A13:$H13)>0),"",IF(A13="","Missing date. ",IF(NOT(ISNUMBER(A13)),"Date is not a real date. ",IF(YEAR(A13)<>Settings!$B$4,"Date outside tax year. ",IF(A13>TODAY(),"Date is in the future. ",""))))) | L13: =IF(NOT(COUNTA($A13:$H13)>0),"",IF(E13="","Missing amount. ",IF(NOT(ISNUMBER(E13)),"Amount is not a number. ",IF(E13<=0,"Amount must be above zero. ","")))) | M13: =IF(NOT(COUNTA($A13:$H13)>0),"",IF(D13="","Missing category. ",IF(COUNTIF(Settings!$B$11:$B$40,D13)=0,"Category not in your list. ",""))) | N13: =IF(AND(ISNUMBER(A13),ISNUMBER(E13),B13<>""),IF(COUNTIFS($A$6:$A$505,A13,$B$6:$B$505,B13,$E$6:$E$505,E13)>1,"Possible duplicate. ",""),"") | O13: =IF(AND(ISNUMBER(E13),E13>=Settings!$B$6,G13<>"Yes"),"Receipt not marked as saved. ","") | P13: =IF(AND(ISNUMBER(E13),E13>=Settings!$B$5),"Large amount: review. ","") -> Large amount: review.
I14: =IF(NOT(COUNTA($A14:$H14)>0),"",IF(K14&L14&M14<>"","ERROR",IF(N14&O14&P14<>"","CHECK","OK"))) | J14: =TRIM(K14&L14&M14&N14&O14&P14) | K14: =IF(NOT(COUNTA($A14:$H14)>0),"",IF(A14="","Missing date. ",IF(NOT(ISNUMBER(A14)),"Date is not a real date. ",IF(YEAR(A14)<>Settings!$B$4,"Date outside tax year. ",IF(A14>TODAY(),"Date is in the future. ",""))))) | L14: =IF(NOT(COUNTA($A14:$H14)>0),"",IF(E14="","Missing amount. ",IF(NOT(ISNUMBER(E14)),"Amount is not a number. ",IF(E14<=0,"Amount must be above zero. ","")))) | M14: =IF(NOT(COUNTA($A14:$H14)>0),"",IF(D14="","Missing category. ",IF(COUNTIF(Settings!$B$11:$B$40,D14)=0,"Category not in your list. ",""))) | N14: =IF(AND(ISNUMBER(A14),ISNUMBER(E14),B14<>""),IF(COUNTIFS($A$6:$A$505,A14,$B$6:$B$505,B14,$E$6:$E$505,E14)>1,"Possible duplicate. ",""),"") | O14: =IF(AND(ISNUMBER(E14),E14>=Settings!$B$6,G14<>"Yes"),"Receipt not marked as saved. ","") | P14: =IF(AND(ISNUMBER(E14),E14>=Settings!$B$5),"Large amount: review. ","")
I15: =IF(NOT(COUNTA($A15:$H15)>0),"",IF(K15&L15&M15<>"","ERROR",IF(N15&O15&P15<>"","CHECK","OK"))) | J15: =TRIM(K15&L15&M15&N15&O15&P15) | K15: =IF(NOT(COUNTA($A15:$H15)>0),"",IF(A15="","Missing date. ",IF(NOT(ISNUMBER(A15)),"Date is not a real date. ",IF(YEAR(A15)<>Settings!$B$4,"Date outside tax year. ",IF(A15>TODAY(),"Date is in the future. ",""))))) | L15: =IF(NOT(COUNTA($A15:$H15)>0),"",IF(E15="","Missing amount. ",IF(NOT(ISNUMBER(E15)),"Amount is not a number. ",IF(E15<=0,"Amount must be above zero. ","")))) | M15: =IF(NOT(COUNTA($A15:$H15)>0),"",IF(D15="","Missing category. ",IF(COUNTIF(Settings!$B$11:$B$40,D15)=0,"Category not in your list. ",""))) | N15: =IF(AND(ISNUMBER(A15),ISNUMBER(E15),B15<>""),IF(COUNTIFS($A$6:$A$505,A15,$B$6:$B$505,B15,$E$6:$E$505,E15)>1,"Possible duplicate. ",""),"") | O15: =IF(AND(ISNUMBER(E15),E15>=Settings!$B$6,G15<>"Yes"),"Receipt not marked as saved. ","") | P15: =IF(AND(ISNUMBER(E15),E15>=Settings!$B$5),"Large amount: review. ","")
I16: =IF(NOT(COUNTA($A16:$H16)>0),"",IF(K16&L16&M16<>"","ERROR",IF(N16&O16&P16<>"","CHECK","OK"))) | J16: =TRIM(K16&L16&M16&N16&O16&P16) | K16: =IF(NOT(COUNTA($A16:$H16)>0),"",IF(A16="","Missing date. ",IF(NOT(ISNUMBER(A16)),"Date is not a real date. ",IF(YEAR(A16)<>Settings!$B$4,"Date outside tax year. ",IF(A16>TODAY(),"Date is in the future. ",""))))) | L16: =IF(NOT(COUNTA($A16:$H16)>0),"",IF(E16="","Missing amount. ",IF(NOT(ISNUMBER(E16)),"Amount is not a number. ",IF(E16<=0,"Amount must be above zero. ","")))) | M16: =IF(NOT(COUNTA($A16:$H16)>0),"",IF(D16="","Missing category. ",IF(COUNTIF(Settings!$B$11:$B$40,D16)=0,"Category not in your list. ",""))) | N16: =IF(AND(ISNUMBER(A16),ISNUMBER(E16),B16<>""),IF(COUNTIFS($A$6:$A$505,A16,$B$6:$B$505,B16,$E$6:$E$505,E16)>1,"Possible duplicate. ",""),"") | O16: =IF(AND(ISNUMBER(E16),E16>=Settings!$B$6,G16<>"Yes"),"Receipt not marked as saved. ","") | P16: =IF(AND(ISNUMBER(E16),E16>=Settings!$B$5),"Large amount: review. ","")
I17: =IF(NOT(COUNTA($A17:$H17)>0),"",IF(K17&L17&M17<>"","ERROR",IF(N17&O17&P17<>"","CHECK","OK"))) | J17: =TRIM(K17&L17&M17&N17&O17&P17) | K17: =IF(NOT(COUNTA($A17:$H17)>0),"",IF(A17="","Missing date. ",IF(NOT(ISNUMBER(A17)),"Date is not a real date. ",IF(YEAR(A17)<>Settings!$B$4,"Date outside tax year. ",IF(A17>TODAY(),"Date is in the future. ",""))))) | L17: =IF(NOT(COUNTA($A17:$H17)>0),"",IF(E17="","Missing amount. ",IF(NOT(ISNUMBER(E17)),"Amount is not a number. ",IF(E17<=0,"Amount must be above zero. ","")))) | M17: =IF(NOT(COUNTA($A17:$H17)>0),"",IF(D17="","Missing category. ",IF(COUNTIF(Settings!$B$11:$B$40,D17)=0,"Category not in your list. ",""))) | N17: =IF(AND(ISNUMBER(A17),ISNUMBER(E17),B17<>""),IF(COUNTIFS($A$6:$A$505,A17,$B$6:$B$505,B17,$E$6:$E$505,E17)>1,"Possible duplicate. ",""),"") | O17: =IF(AND(ISNUMBER(E17),E17>=Settings!$B$6,G17<>"Yes"),"Receipt not marked as saved. ","") | P17: =IF(AND(ISNUMBER(E17),E17>=Settings!$B$5),"Large amount: review. ","")
I18: =IF(NOT(COUNTA($A18:$H18)>0),"",IF(K18&L18&M18<>"","ERROR",IF(N18&O18&P18<>"","CHECK","OK"))) | J18: =TRIM(K18&L18&M18&N18&O18&P18) | K18: =IF(NOT(COUNTA($A18:$H18)>0),"",IF(A18="","Missing date. ",IF(NOT(ISNUMBER(A18)),"Date is not a real date. ",IF(YEAR(A18)<>Settings!$B$4,"Date outside tax year. ",IF(A18>TODAY(),"Date is in the future. ",""))))) | L18: =IF(NOT(COUNTA($A18:$H18)>0),"",IF(E18="","Missing amount. ",IF(NOT(ISNUMBER(E18)),"Amount is not a number. ",IF(E18<=0,"Amount must be above zero. ","")))) | M18: =IF(NOT(COUNTA($A18:$H18)>0),"",IF(D18="","Missing category. ",IF(COUNTIF(Settings!$B$11:$B$40,D18)=0,"Category not in your list. ",""))) | N18: =IF(AND(ISNUMBER(A18),ISNUMBER(E18),B18<>""),IF(COUNTIFS($A$6:$A$505,A18,$B$6:$B$505,B18,$E$6:$E$505,E18)>1,"Possible duplicate. ",""),"") | O18: =IF(AND(ISNUMBER(E18),E18>=Settings!$B$6,G18<>"Yes"),"Receipt not marked as saved. ","") | P18: =IF(AND(ISNUMBER(E18),E18>=Settings!$B$5),"Large amount: review. ","")
I19: =IF(NOT(COUNTA($A19:$H19)>0),"",IF(K19&L19&M19<>"","ERROR",IF(N19&O19&P19<>"","CHECK","OK"))) | J19: =TRIM(K19&L19&M19&N19&O19&P19) | K19: =IF(NOT(COUNTA($A19:$H19)>0),"",IF(A19="","Missing date. ",IF(NOT(ISNUMBER(A19)),"Date is not a real date. ",IF(YEAR(A19)<>Settings!$B$4,"Date outside tax year. ",IF(A19>TODAY(),"Date is in the future. ",""))))) | L19: =IF(NOT(COUNTA($A19:$H19)>0),"",IF(E19="","Missing amount. ",IF(NOT(ISNUMBER(E19)),"Amount is not a number. ",IF(E19<=0,"Amount must be above zero. ","")))) | M19: =IF(NOT(COUNTA($A19:$H19)>0),"",IF(D19="","Missing category. ",IF(COUNTIF(Settings!$B$11:$B$40,D19)=0,"Category not in your list. ",""))) | N19: =IF(AND(ISNUMBER(A19),ISNUMBER(E19),B19<>""),IF(COUNTIFS($A$6:$A$505,A19,$B$6:$B$505,B19,$E$6:$E$505,E19)>1,"Possible duplicate. ",""),"") | O19: =IF(AND(ISNUMBER(E19),E19>=Settings!$B$6,G19<>"Yes"),"Receipt not marked as saved. ","") | P19: =IF(AND(ISNUMBER(E19),E19>=Settings!$B$5),"Large amount: review. ","")
I20: =IF(NOT(COUNTA($A20:$H20)>0),"",IF(K20&L20&M20<>"","ERROR",IF(N20&O20&P20<>"","CHECK","OK"))) | J20: =TRIM(K20&L20&M20&N20&O20&P20) | K20: =IF(NOT(COUNTA($A20:$H20)>0),"",IF(A20="","Missing date. ",IF(NOT(ISNUMBER(A20)),"Date is not a real date. ",IF(YEAR(A20)<>Settings!$B$4,"Date outside tax year. ",IF(A20>TODAY(),"Date is in the future. ",""))))) | L20: =IF(NOT(COUNTA($A20:$H20)>0),"",IF(E20="","Missing amount. ",IF(NOT(ISNUMBER(E20)),"Amount is not a number. ",IF(E20<=0,"Amount must be above zero. ","")))) | M20: =IF(NOT(COUNTA($A20:$H20)>0),"",IF(D20="","Missing category. ",IF(COUNTIF(Settings!$B$11:$B$40,D20)=0,"Category not in your list. ",""))) | N20: =IF(AND(ISNUMBER(A20),ISNUMBER(E20),B20<>""),IF(COUNTIFS($A$6:$A$505,A20,$B$6:$B$505,B20,$E$6:$E$505,E20)>1,"Possible duplicate. ",""),"") | O20: =IF(AND(ISNUMBER(E20),E20>=Settings!$B$6,G20<>"Yes"),"Receipt not marked as saved. ","") | P20: =IF(AND(ISNUMBER(E20),E20>=Settings!$B$5),"Large amount: review. ","")
I21: =IF(NOT(COUNTA($A21:$H21)>0),"",IF(K21&L21&M21<>"","ERROR",IF(N21&O21&P21<>"","CHECK","OK"))) | J21: =TRIM(K21&L21&M21&N21&O21&P21) | K21: =IF(NOT(COUNTA($A21:$H21)>0),"",IF(A21="","Missing date. ",IF(NOT(ISNUMBER(A21)),"Date is not a real date. ",IF(YEAR(A21)<>Settings!$B$4,"Date outside tax year. ",IF(A21>TODAY(),"Date is in the future. ",""))))) | L21: =IF(NOT(COUNTA($A21:$H21)>0),"",IF(E21="","Missing amount. ",IF(NOT(ISNUMBER(E21)),"Amount is not a number. ",IF(E21<=0,"Amount must be above zero. ","")))) | M21: =IF(NOT(COUNTA($A21:$H21)>0),"",IF(D21="","Missing category. ",IF(COUNTIF(Settings!$B$11:$B$40,D21)=0,"Category not in your list. ",""))) | N21: =IF(AND(ISNUMBER(A21),ISNUMBER(E21),B21<>""),IF(COUNTIFS($A$6:$A$505,A21,$B$6:$B$505,B21,$E$6:$E$505,E21)>1,"Possible duplicate. ",""),"") | O21: =IF(AND(ISNUMBER(E21),E21>=Settings!$B$6,G21<>"Yes"),"Receipt not marked as saved. ","") | P21: =IF(AND(ISNUMBER(E21),E21>=Settings!$B$5),"Large amount: review. ","")
I22: =IF(NOT(COUNTA($A22:$H22)>0),"",IF(K22&L22&M22<>"","ERROR",IF(N22&O22&P22<>"","CHECK","OK"))) | J22: =TRIM(K22&L22&M22&N22&O22&P22) | K22: =IF(NOT(COUNTA($A22:$H22)>0),"",IF(A22="","Missing date. ",IF(NOT(ISNUMBER(A22)),"Date is not a real date. ",IF(YEAR(A22)<>Settings!$B$4,"Date outside tax year. ",IF(A22>TODAY(),"Date is in the future. ",""))))) | L22: =IF(NOT(COUNTA($A22:$H22)>0),"",IF(E22="","Missing amount. ",IF(NOT(ISNUMBER(E22)),"Amount is not a number. ",IF(E22<=0,"Amount must be above zero. ","")))) | M22: =IF(NOT(COUNTA($A22:$H22)>0),"",IF(D22="","Missing category. ",IF(COUNTIF(Settings!$B$11:$B$40,D22)=0,"Category not in your list. ",""))) | N22: =IF(AND(ISNUMBER(A22),ISNUMBER(E22),B22<>""),IF(COUNTIFS($A$6:$A$505,A22,$B$6:$B$505,B22,$E$6:$E$505,E22)>1,"Possible duplicate. ",""),"") | O22: =IF(AND(ISNUMBER(E22),E22>=Settings!$B$6,G22<>"Yes"),"Receipt not marked as saved. ","") | P22: =IF(AND(ISNUMBER(E22),E22>=Settings!$B$5),"Large amount: review. ","")
I23: =IF(NOT(COUNTA($A23:$H23)>0),"",IF(K23&L23&M23<>"","ERROR",IF(N23&O23&P23<>"","CHECK","OK"))) | J23: =TRIM(K23&L23&M23&N23&O23&P23) | K23: =IF(NOT(COUNTA($A23:$H23)>0),"",IF(A23="","Missing date. ",IF(NOT(ISNUMBER(A23)),"Date is not a real date. ",IF(YEAR(A23)<>Settings!$B$4,"Date outside tax year. ",IF(A23>TODAY(),"Date is in the future. ",""))))) | L23: =IF(NOT(COUNTA($A23:$H23)>0),"",IF(E23="","Missing amount. ",IF(NOT(ISNUMBER(E23)),"Amount is not a number. ",IF(E23<=0,"Amount must be above zero. ","")))) | M23: =IF(NOT(COUNTA($A23:$H23)>0),"",IF(D23="","Missing category. ",IF(COUNTIF(Settings!$B$11:$B$40,D23)=0,"Category not in your list. ",""))) | N23: =IF(AND(ISNUMBER(A23),ISNUMBER(E23),B23<>""),IF(COUNTIFS($A$6:$A$505,A23,$B$6:$B$505,B23,$E$6:$E$505,E23)>1,"Possible duplicate. ",""),"") | O23: =IF(AND(ISNUMBER(E23),E23>=Settings!$B$6,G23<>"Yes"),"Receipt not marked as saved. ","") | P23: =IF(AND(ISNUMBER(E23),E23>=Settings!$B$5),"Large amount: review. ","")
I24: =IF(NOT(COUNTA($A24:$H24)>0),"",IF(K24&L24&M24<>"","ERROR",IF(N24&O24&P24<>"","CHECK","OK"))) | J24: =TRIM(K24&L24&M24&N24&O24&P24) | K24: =IF(NOT(COUNTA($A24:$H24)>0),"",IF(A24="","Missing date. ",IF(NOT(ISNUMBER(A24)),"Date is not a real date. ",IF(YEAR(A24)<>Settings!$B$4,"Date outside tax year. ",IF(A24>TODAY(),"Date is in the future. ",""))))) | L24: =IF(NOT(COUNTA($A24:$H24)>0),"",IF(E24="","Missing amount. ",IF(NOT(ISNUMBER(E24)),"Amount is not a number. ",IF(E24<=0,"Amount must be above zero. ","")))) | M24: =IF(NOT(COUNTA($A24:$H24)>0),"",IF(D24="","Missing category. ",IF(COUNTIF(Settings!$B$11:$B$40,D24)=0,"Category not in your list. ",""))) | N24: =IF(AND(ISNUMBER(A24),ISNUMBER(E24),B24<>""),IF(COUNTIFS($A$6:$A$505,A24,$B$6:$B$505,B24,$E$6:$E$505,E24)>1,"Possible duplicate. ",""),"") | O24: =IF(AND(ISNUMBER(E24),E24>=Settings!$B$6,G24<>"Yes"),"Receipt not marked as saved. ","") | P24: =IF(AND(ISNUMBER(E24),E24>=Settings!$B$5),"Large amount: review. ","")
I25: =IF(NOT(COUNTA($A25:$H25)>0),"",IF(K25&L25&M25<>"","ERROR",IF(N25&O25&P25<>"","CHECK","OK"))) | J25: =TRIM(K25&L25&M25&N25&O25&P25) | K25: =IF(NOT(COUNTA($A25:$H25)>0),"",IF(A25="","Missing date. ",IF(NOT(ISNUMBER(A25)),"Date is not a real date. ",IF(YEAR(A25)<>Settings!$B$4,"Date outside tax year. ",IF(A25>TODAY(),"Date is in the future. ",""))))) | L25: =IF(NOT(COUNTA($A25:$H25)>0),"",IF(E25="","Missing amount. ",IF(NOT(ISNUMBER(E25)),"Amount is not a number. ",IF(E25<=0,"Amount must be above zero. ","")))) | M25: =IF(NOT(COUNTA($A25:$H25)>0),"",IF(D25="","Missing category. ",IF(COUNTIF(Settings!$B$11:$B$40,D25)=0,"Category not in your list. ",""))) | N25: =IF(AND(ISNUMBER(A25),ISNUMBER(E25),B25<>""),IF(COUNTIFS($A$6:$A$505,A25,$B$6:$B$505,B25,$E$6:$E$505,E25)>1,"Possible duplicate. ",""),"") | O25: =IF(AND(ISNUMBER(E25),E25>=Settings!$B$6,G25<>"Yes"),"Receipt not marked as saved. ","") | P25: =IF(AND(ISNUMBER(E25),E25>=Settings!$B$5),"Large amount: review. ","")
... I505: =IF(NOT(COUNTA($A505:$H505)>0),"",IF(K505&L505&M505<>"","ERROR",IF(N505&O505&P505<>"","CHECK","OK"))) | J505: =TRIM(K505&L505&M505&N505&O505&P505) | K505: =IF(NOT(COUNTA($A505:$H505)>0),"",IF(A505="","Missing date. ",IF(NOT(ISNUMBER(A505)),"Date is not a real date. ",IF(YEAR(A505)<>Settings!$B$4,"Date outside tax year. ",IF(A505>TODAY(),"Date is in the future. ",""))))) | L505: =IF(NOT(COUNTA($A505:$H505)>0),"",IF(E505="","Missing amount. ",IF(NOT(ISNUMBER(E505)),"Amount is not a number. ",IF(E505<=0,"Amount must be above zero. ","")))) | M505: =IF(NOT(COUNTA($A505:$H505)>0),"",IF(D505="","Missing category. ",IF(COUNTIF(Settings!$B$11:$B$40,D505)=0,"Category not in your list. ",""))) | N505: =IF(AND(ISNUMBER(A505),ISNUMBER(E505),B505<>""),IF(COUNTIFS($A$6:$A$505,A505,$B$6:$B$505,B505,$E$6:$E$505,E505)>1,"Possible duplicate. ",""),"") | O505: =IF(AND(ISNUMBER(E505),E505>=Settings!$B$6,G505<>"Yes"),"Receipt not marked as saved. ","") | P505: =IF(AND(ISNUMBER(E505),E505>=Settings!$B$5),"Large amount: review. ","")

Sheet Summary
A1: Summary & checks
A2: =" Tax year "&Settings!$B$4&" | amounts in "&Settings!$B$7 -> Tax year 2026 | amounts in USD
A4: Overall | B4: =IF(B5=0,"Add your first expense",IF(AND(B6=0,B7=0,B13="YES",B14="YES"),"ALL CHECKS PASSED",B6&" error(s), "&B7&" to review")) -> 3 error(s), 4 to review
A5: Rows entered | B5: =COUNTIF(Expenses!$I$6:$I$505,"OK")+COUNTIF(Expenses!$I$6:$I$505,"CHECK")+COUNTIF(Expenses!$I$6:$I$505,"ERROR") -> 8
A6: Rows with ERRORS (left out of totals) | B6: =COUNTIF(Expenses!$I$6:$I$505,"ERROR") -> 3
A7: Rows to CHECK (counted, please review) | B7: =COUNTIF(Expenses!$I$6:$I$505,"CHECK") -> 4
A8: Rows OK | B8: =COUNTIF(Expenses!$I$6:$I$505,"OK") -> 1
A9: Possible duplicates | B9: =COUNTIF(Expenses!$N$6:$N$505,"Possible*") -> 2
A10: Receipts not marked as saved | B10: =COUNTIF(Expenses!$O$6:$O$505,"Receipt*") -> 1
A11: Amount left out of totals (rows with errors) | B11: =SUMIFS(Expenses!$E$6:$E$505,Expenses!$I$6:$I$505,"ERROR") -> 1247.76
A12: Total counted (OK + CHECK) | B12: =SUMIFS(Expenses!$E$6:$E$505,Expenses!$I$6:$I$505,"OK")+SUMIFS(Expenses!$E$6:$E$505,Expenses!$I$6:$I$505,"CHECK") -> 1780.48
A13: Category totals add up to total? | B13: =IF(ROUND(SUM($B$24:$B$53)-B12,2)=0,"YES","NO") -> YES
A14: Monthly totals add up to total? | B14: =IF(ROUND(SUM($E$24:$E$35)-B12,2)=0,"YES","NO") -> YES
A22: By category | D22: By month
A23: Category | B23: Total counted | D23: Month | E23: Total counted
A24: =IF(Settings!$B$11="","",Settings!$B$11) -> Advertising & marketing | B24: =IF(A24="","",SUMIFS(Expenses!$E$6:$E$505,Expenses!$D$6:$D$505,A24,Expenses!$I$6:$I$505,"OK")+SUMIFS(Expenses!$E$6:$E$505,Expenses!$D$6:$D$505,A24,Expenses!$I$6:$I$505,"CHECK")) -> 0 | D24: January | E24: =SUMIFS(Expenses!$E$6:$E$505,Expenses!$A$6:$A$505,">="&DATE(Settings!$B$4,1,1),Expenses!$A$6:$A$505,"<"&DATE(Settings!$B$4,2,1),Expenses!$I$6:$I$505,"OK")+SUMIFS(Expenses!$E$6:$E$505,Expenses!$A$6:$A$505,">="&DATE(Settings!$B$4,1,1),Expenses!$A$6:$A$505,"<"&DATE(Settings!$B$4,2,1),Expenses!$I$6:$I$505,"CHECK") -> 168.18
A25: =IF(Settings!$B$12="","",Settings!$B$12) -> Bank & payment fees | B25: =IF(A25="","",SUMIFS(Expenses!$E$6:$E$505,Expenses!$D$6:$D$505,A25,Expenses!$I$6:$I$505,"OK")+SUMIFS(Expenses!$E$6:$E$505,Expenses!$D$6:$D$505,A25,Expenses!$I$6:$I$505,"CHECK")) -> 0 | D25: February | E25: =SUMIFS(Expenses!$E$6:$E$505,Expenses!$A$6:$A$505,">="&DATE(Settings!$B$4,2,1),Expenses!$A$6:$A$505,"<"&DATE(Settings!$B$4,3,1),Expenses!$I$6:$I$505,"OK")+SUMIFS(Expenses!$E$6:$E$505,Expenses!$A$6:$A$505,">="&DATE(Settings!$B$4,2,1),Expenses!$A$6:$A$505,"<"&DATE(Settings!$B$4,3,1),Expenses!$I$6:$I$505,"CHECK") -> 412.3
A26: =IF(Settings!$B$13="","",Settings!$B$13) -> Equipment | B26: =IF(A26="","",SUMIFS(Expenses!$E$6:$E$505,Expenses!$D$6:$D$505,A26,Expenses!$I$6:$I$505,"OK")+SUMIFS(Expenses!$E$6:$E$505,Expenses!$D$6:$D$505,A26,Expenses!$I$6:$I$505,"CHECK")) -> 0 | D26: March | E26: =SUMIFS(Expenses!$E$6:$E$505,Expenses!$A$6:$A$505,">="&DATE(Settings!$B$4,3,1),Expenses!$A$6:$A$505,"<"&DATE(Settings!$B$4,4,1),Expenses!$I$6:$I$505,"OK")+SUMIFS(Expenses!$E$6:$E$505,Expenses!$A$6:$A$505,">="&DATE(Settings!$B$4,3,1),Expenses!$A$6:$A$505,"<"&DATE(Settings!$B$4,4,1),Expenses!$I$6:$I$505,"CHECK") -> 1200
A27: =IF(Settings!$B$14="","",Settings!$B$14) -> Meals | B27: =IF(A27="","",SUMIFS(Expenses!$E$6:$E$505,Expenses!$D$6:$D$505,A27,Expenses!$I$6:$I$505,"OK")+SUMIFS(Expenses!$E$6:$E$505,Expenses!$D$6:$D$505,A27,Expenses!$I$6:$I$505,"CHECK")) -> 0 | D27: April | E27: =SUMIFS(Expenses!$E$6:$E$505,Expenses!$A$6:$A$505,">="&DATE(Settings!$B$4,4,1),Expenses!$A$6:$A$505,"<"&DATE(Settings!$B$4,5,1),Expenses!$I$6:$I$505,"OK")+SUMIFS(Expenses!$E$6:$E$505,Expenses!$A$6:$A$505,">="&DATE(Settings!$B$4,4,1),Expenses!$A$6:$A$505,"<"&DATE(Settings!$B$4,5,1),Expenses!$I$6:$I$505,"CHECK") -> 0
A28: =IF(Settings!$B$15="","",Settings!$B$15) -> Office supplies | B28: =IF(A28="","",SUMIFS(Expenses!$E$6:$E$505,Expenses!$D$6:$D$505,A28,Expenses!$I$6:$I$505,"OK")+SUMIFS(Expenses!$E$6:$E$505,Expenses!$D$6:$D$505,A28,Expenses!$I$6:$I$505,"CHECK")) -> 48.2 | D28: May | E28: =SUMIFS(Expenses!$E$6:$E$505,Expenses!$A$6:$A$505,">="&DATE(Settings!$B$4,5,1),Expenses!$A$6:$A$505,"<"&DATE(Settings!$B$4,6,1),Expenses!$I$6:$I$505,"OK")+SUMIFS(Expenses!$E$6:$E$505,Expenses!$A$6:$A$505,">="&DATE(Settings!$B$4,5,1),Expenses!$A$6:$A$505,"<"&DATE(Settings!$B$4,6,1),Expenses!$I$6:$I$505,"CHECK") -> 0
A29: =IF(Settings!$B$16="","",Settings!$B$16) -> Phone & internet | B29: =IF(A29="","",SUMIFS(Expenses!$E$6:$E$505,Expenses!$D$6:$D$505,A29,Expenses!$I$6:$I$505,"OK")+SUMIFS(Expenses!$E$6:$E$505,Expenses!$D$6:$D$505,A29,Expenses!$I$6:$I$505,"CHECK")) -> 0 | D29: June | E29: =SUMIFS(Expenses!$E$6:$E$505,Expenses!$A$6:$A$505,">="&DATE(Settings!$B$4,6,1),Expenses!$A$6:$A$505,"<"&DATE(Settings!$B$4,7,1),Expenses!$I$6:$I$505,"OK")+SUMIFS(Expenses!$E$6:$E$505,Expenses!$A$6:$A$505,">="&DATE(Settings!$B$4,6,1),Expenses!$A$6:$A$505,"<"&DATE(Settings!$B$4,7,1),Expenses!$I$6:$I$505,"CHECK") -> 0
A30: =IF(Settings!$B$17="","",Settings!$B$17) -> Professional services | B30: =IF(A30="","",SUMIFS(Expenses!$E$6:$E$505,Expenses!$D$6:$D$505,A30,Expenses!$I$6:$I$505,"OK")+SUMIFS(Expenses!$E$6:$E$505,Expenses!$D$6:$D$505,A30,Expenses!$I$6:$I$505,"CHECK")) -> 0 | D30: July | E30: =SUMIFS(Expenses!$E$6:$E$505,Expenses!$A$6:$A$505,">="&DATE(Settings!$B$4,7,1),Expenses!$A$6:$A$505,"<"&DATE(Settings!$B$4,8,1),Expenses!$I$6:$I$505,"OK")+SUMIFS(Expenses!$E$6:$E$505,Expenses!$A$6:$A$505,">="&DATE(Settings!$B$4,7,1),Expenses!$A$6:$A$505,"<"&DATE(Settings!$B$4,8,1),Expenses!$I$6:$I$505,"CHECK") -> 0
A31: =IF(Settings!$B$18="","",Settings!$B$18) -> Rent | B31: =IF(A31="","",SUMIFS(Expenses!$E$6:$E$505,Expenses!$D$6:$D$505,A31,Expenses!$I$6:$I$505,"OK")+SUMIFS(Expenses!$E$6:$E$505,Expenses!$D$6:$D$505,A31,Expenses!$I$6:$I$505,"CHECK")) -> 1200 | D31: August | E31: =SUMIFS(Expenses!$E$6:$E$505,Expenses!$A$6:$A$505,">="&DATE(Settings!$B$4,8,1),Expenses!$A$6:$A$505,"<"&DATE(Settings!$B$4,9,1),Expenses!$I$6:$I$505,"OK")+SUMIFS(Expenses!$E$6:$E$505,Expenses!$A$6:$A$505,">="&DATE(Settings!$B$4,8,1),Expenses!$A$6:$A$505,"<"&DATE(Settings!$B$4,9,1),Expenses!$I$6:$I$505,"CHECK") -> 0
A32: =IF(Settings!$B$19="","",Settings!$B$19) -> Software & subscriptions | B32: =IF(A32="","",SUMIFS(Expenses!$E$6:$E$505,Expenses!$D$6:$D$505,A32,Expenses!$I$6:$I$505,"OK")+SUMIFS(Expenses!$E$6:$E$505,Expenses!$D$6:$D$505,A32,Expenses!$I$6:$I$505,"CHECK")) -> 119.98 | D32: September | E32: =SUMIFS(Expenses!$E$6:$E$505,Expenses!$A$6:$A$505,">="&DATE(Settings!$B$4,9,1),Expenses!$A$6:$A$505,"<"&DATE(Settings!$B$4,10,1),Expenses!$I$6:$I$505,"OK")+SUMIFS(Expenses!$E$6:$E$505,Expenses!$A$6:$A$505,">="&DATE(Settings!$B$4,9,1),Expenses!$A$6:$A$505,"<"&DATE(Settings!$B$4,10,1),Expenses!$I$6:$I$505,"CHECK") -> 0
A33: =IF(Settings!$B$20="","",Settings!$B$20) -> Training & education | B33: =IF(A33="","",SUMIFS(Expenses!$E$6:$E$505,Expenses!$D$6:$D$505,A33,Expenses!$I$6:$I$505,"OK")+SUMIFS(Expenses!$E$6:$E$505,Expenses!$D$6:$D$505,A33,Expenses!$I$6:$I$505,"CHECK")) -> 0 | D33: October | E33: =SUMIFS(Expenses!$E$6:$E$505,Expenses!$A$6:$A$505,">="&DATE(Settings!$B$4,10,1),Expenses!$A$6:$A$505,"<"&DATE(Settings!$B$4,11,1),Expenses!$I$6:$I$505,"OK")+SUMIFS(Expenses!$E$6:$E$505,Expenses!$A$6:$A$505,">="&DATE(Settings!$B$4,10,1),Expenses!$A$6:$A$505,"<"&DATE(Settings!$B$4,11,1),Expenses!$I$6:$I$505,"CHECK") -> 0
A34: =IF(Settings!$B$21="","",Settings!$B$21) -> Travel | B34: =IF(A34="","",SUMIFS(Expenses!$E$6:$E$505,Expenses!$D$6:$D$505,A34,Expenses!$I$6:$I$505,"OK")+SUMIFS(Expenses!$E$6:$E$505,Expenses!$D$6:$D$505,A34,Expenses!$I$6:$I$505,"CHECK")) -> 412.3 | D34: November | E34: =SUMIFS(Expenses!$E$6:$E$505,Expenses!$A$6:$A$505,">="&DATE(Settings!$B$4,11,1),Expenses!$A$6:$A$505,"<"&DATE(Settings!$B$4,12,1),Expenses!$I$6:$I$505,"OK")+SUMIFS(Expenses!$E$6:$E$505,Expenses!$A$6:$A$505,">="&DATE(Settings!$B$4,11,1),Expenses!$A$6:$A$505,"<"&DATE(Settings!$B$4,12,1),Expenses!$I$6:$I$505,"CHECK") -> 0
A35: =IF(Settings!$B$22="","",Settings!$B$22) -> Vehicle | B35: =IF(A35="","",SUMIFS(Expenses!$E$6:$E$505,Expenses!$D$6:$D$505,A35,Expenses!$I$6:$I$505,"OK")+SUMIFS(Expenses!$E$6:$E$505,Expenses!$D$6:$D$505,A35,Expenses!$I$6:$I$505,"CHECK")) -> 0 | D35: December | E35: =SUMIFS(Expenses!$E$6:$E$505,Expenses!$A$6:$A$505,">="&DATE(Settings!$B$4,12,1),Expenses!$A$6:$A$505,"<"&DATE(Settings!$B$4,13,1),Expenses!$I$6:$I$505,"OK")+SUMIFS(Expenses!$E$6:$E$505,Expenses!$A$6:$A$505,">="&DATE(Settings!$B$4,12,1),Expenses!$A$6:$A$505,"<"&DATE(Settings!$B$4,13,1),Expenses!$I$6:$I$505,"CHECK") -> 0
A36: =IF(Settings!$B$23="","",Settings!$B$23) -> Other | B36: =IF(A36="","",SUMIFS(Expenses!$E$6:$E$505,Expenses!$D$6:$D$505,A36,Expenses!$I$6:$I$505,"OK")+SUMIFS(Expenses!$E$6:$E$505,Expenses!$D$6:$D$505,A36,Expenses!$I$6:$I$505,"CHECK")) -> 0
A37: =IF(Settings!$B$24="","",Settings!$B$24) | B37: =IF(A37="","",SUMIFS(Expenses!$E$6:$E$505,Expenses!$D$6:$D$505,A37,Expenses!$I$6:$I$505,"OK")+SUMIFS(Expenses!$E$6:$E$505,Expenses!$D$6:$D$505,A37,Expenses!$I$6:$I$505,"CHECK"))
A38: =IF(Settings!$B$25="","",Settings!$B$25) | B38: =IF(A38="","",SUMIFS(Expenses!$E$6:$E$505,Expenses!$D$6:$D$505,A38,Expenses!$I$6:$I$505,"OK")+SUMIFS(Expenses!$E$6:$E$505,Expenses!$D$6:$D$505,A38,Expenses!$I$6:$I$505,"CHECK"))
A39: =IF(Settings!$B$26="","",Settings!$B$26) | B39: =IF(A39="","",SUMIFS(Expenses!$E$6:$E$505,Expenses!$D$6:$D$505,A39,Expenses!$I$6:$I$505,"OK")+SUMIFS(Expenses!$E$6:$E$505,Expenses!$D$6:$D$505,A39,Expenses!$I$6:$I$505,"CHECK"))
A40: =IF(Settings!$B$27="","",Settings!$B$27) | B40: =IF(A40="","",SUMIFS(Expenses!$E$6:$E$505,Expenses!$D$6:$D$505,A40,Expenses!$I$6:$I$505,"OK")+SUMIFS(Expenses!$E$6:$E$505,Expenses!$D$6:$D$505,A40,Expenses!$I$6:$I$505,"CHECK"))
A41: =IF(Settings!$B$28="","",Settings!$B$28) | B41: =IF(A41="","",SUMIFS(Expenses!$E$6:$E$505,Expenses!$D$6:$D$505,A41,Expenses!$I$6:$I$505,"OK")+SUMIFS(Expenses!$E$6:$E$505,Expenses!$D$6:$D$505,A41,Expenses!$I$6:$I$505,"CHECK"))
A42: =IF(Settings!$B$29="","",Settings!$B$29) | B42: =IF(A42="","",SUMIFS(Expenses!$E$6:$E$505,Expenses!$D$6:$D$505,A42,Expenses!$I$6:$I$505,"OK")+SUMIFS(Expenses!$E$6:$E$505,Expenses!$D$6:$D$505,A42,Expenses!$I$6:$I$505,"CHECK"))
A43: =IF(Settings!$B$30="","",Settings!$B$30) | B43: =IF(A43="","",SUMIFS(Expenses!$E$6:$E$505,Expenses!$D$6:$D$505,A43,Expenses!$I$6:$I$505,"OK")+SUMIFS(Expenses!$E$6:$E$505,Expenses!$D$6:$D$505,A43,Expenses!$I$6:$I$505,"CHECK"))
A44: =IF(Settings!$B$31="","",Settings!$B$31) | B44: =IF(A44="","",SUMIFS(Expenses!$E$6:$E$505,Expenses!$D$6:$D$505,A44,Expenses!$I$6:$I$505,"OK")+SUMIFS(Expenses!$E$6:$E$505,Expenses!$D$6:$D$505,A44,Expenses!$I$6:$I$505,"CHECK"))
A45: =IF(Settings!$B$32="","",Settings!$B$32) | B45: =IF(A45="","",SUMIFS(Expenses!$E$6:$E$505,Expenses!$D$6:$D$505,A45,Expenses!$I$6:$I$505,"OK")+SUMIFS(Expenses!$E$6:$E$505,Expenses!$D$6:$D$505,A45,Expenses!$I$6:$I$505,"CHECK"))
A46: =IF(Settings!$B$33="","",Settings!$B$33) | B46: =IF(A46="","",SUMIFS(Expenses!$E$6:$E$505,Expenses!$D$6:$D$505,A46,Expenses!$I$6:$I$505,"OK")+SUMIFS(Expenses!$E$6:$E$505,Expenses!$D$6:$D$505,A46,Expenses!$I$6:$I$505,"CHECK"))
A47: =IF(Settings!$B$34="","",Settings!$B$34) | B47: =IF(A47="","",SUMIFS(Expenses!$E$6:$E$505,Expenses!$D$6:$D$505,A47,Expenses!$I$6:$I$505,"OK")+SUMIFS(Expenses!$E$6:$E$505,Expenses!$D$6:$D$505,A47,Expenses!$I$6:$I$505,"CHECK"))
A48: =IF(Settings!$B$35="","",Settings!$B$35) | B48: =IF(A48="","",SUMIFS(Expenses!$E$6:$E$505,Expenses!$D$6:$D$505,A48,Expenses!$I$6:$I$505,"OK")+SUMIFS(Expenses!$E$6:$E$505,Expenses!$D$6:$D$505,A48,Expenses!$I$6:$I$505,"CHECK"))
...

Sheet Settings
A1: Settings
A2: Yellow cells are yours to change. Everything else updates automatically.
A4: Tax year | B4: 2026 | C4: The year this tracker covers. Dates outside it are flagged.
A5: Large expense: review at or above | B5: 1000 | C5: Your own review rule (example value). Flags, never blocks.
A6: Receipt required at or above | B6: 75 | C6: Your own record-keeping rule (example value), not a legal threshold. Ask your tax professional what records you need.
A7: Currency label | B7: USD | C7: Shown in headers only; no conversion is done.
A10: Categories | C10: Generic examples. Rename or add your own (up to 30). Map them to your tax forms with a tax professional.
B11: Advertising & marketing
B12: Bank & payment fees
B13: Equipment
B14: Meals
B15: Office supplies
B16: Phone & internet
B17: Professional services
B18: Rent
B19: Software & subscriptions
B20: Training & education
B21: Travel
B22: Vehicle
B23: Other
A43: Payment methods
B44: Card
B45: Bank transfer
B46: Cash
B47: Check
B48: Other
